Workbook

Sheet Course Information
C1: PES Institute of Technology & Management, Shivamogga
C2: CO, PO & PSO Attainment Format
A4: Title of the Program | F4: UNDER GRADUATE PROGRAM | K4: Department | N4: Information Science & Engg
A5: Academic Year | F5: 2026-27 | K5: Semester & Section | N5: III | P5: A
A6: Course Name | F6: DATA STRUCTURE AND APPLICATIONS | K6: Number of Students | N6: 57
A7: Course Code | F7: 1BCS305 | K7: NBA Code
A8: Name of the Faculty | F8: Thara K L | K8: Head of the Department
A9: Course Target | K9: Maximum SEE Marks | N9: 50
A10: CO's | C10: CO-PO Mapping | O10: CO-PSO Mapping
C11: PO's | O11: PSO's
C12: PO1 | D12: PO2 | E12: PO3 | F12: PO4 | G12: PO5 | H12: PO6 | I12: PO7 | J12: PO8 | K12: PO9 | L12: PO10 | M12: PO11 | O12: PSO1 | P12: PSO2 | Q12: PSO3
A13: =CONCATENATE(MID($A$10,1,2),MID($N$7,2,3),".",1) -> CO.1
A14: =CONCATENATE(MID($A$10,1,2),MID($N$7,2,3),".",2) -> CO.2
A15: =CONCATENATE(MID($A$10,1,2),MID($N$7,2,3),".",3) -> CO.3
A16: =CONCATENATE(MID($A$10,1,2),MID($N$7,2,3),".",4) -> CO.4
A17: =CONCATENATE(MID($A$10,1,2),MID($N$7,2,3),".",5) -> CO.5
A18: =CONCATENATE(MID($A$10,1,2),MID($N$7,2,3),".",6) -> CO.6
A19: Achievable | C19: =IFERROR(ROUNDUP((SUM(C13:C18))/(COUNT(C13:C18)),2),"NA") -> NA | D19: =IFERROR(ROUNDUP((SUM(D13:D18))/(COUNT(D13:D18)),2),"NA") -> NA | E19: =IFERROR(ROUNDUP((SUM(E13:E18))/(COUNT(E13:E18)),2),"NA") -> NA | F19: =IFERROR(ROUNDUP((SUM(F13:F18))/(COUNT(F13:F18)),2),"NA") -> NA | G19: =IFERROR(ROUNDUP((SUM(G13:G18))/(COUNT(G13:G18)),2),"NA") -> NA | H19: =IFERROR(ROUNDUP((SUM(H13:H18))/(COUNT(H13:H18)),2),"NA") -> NA | I19: =IFERROR(ROUNDUP((SUM(I13:I18))/(COUNT(I13:I18)),2),"NA") -> NA | J19: =IFERROR(ROUNDUP((SUM(J13:J18))/(COUNT(J13:J18)),2),"NA") -> NA | ... Q19: =IFERROR(ROUNDUP((SUM(Q13:Q18))/(COUNT(Q13:Q18)),2),"NA") -> NA
A22: Student Information | I22: CIE Marks Allocation | N22: Question - CO Mapping
A23: Sl. No. | B23: USN | D23: Name | I23: Q. No. | J23: 1st IA | K23: 2nd IA | L23: RT1 | N23: Q. No. | O23: 1st IA | P23: 2nd IA
A24: 1 | I24: 1a / 2a | N24: 1a / 2a | Q24: RT1
A25: 2 | I25: 1b / 2b | N25: 1b / 2b
A26: 3 | I26: 1c / 2c | N26: 1c / 2c
A27: 4 | I27: 3a / 4a | N27: 3a / 4a
A28: 5 | I28: 3b / 4b | N28: 3b / 4b
A29: 6 | I29: 3c / 4c | N29: 3c / 4c
A30: 7 | I30: 5a / 6a | N30: 5a / 6a
A31: 8 | I31: 5b / 6b | N31: 5b / 6b
A32: 9 | I32: 5c / 6c | L32: RT2 | N32: 5c / 6c
A33: 10 | Q33: RT2
A34: 11
A35: 12
A36: 13 | I36: LAB CIE | N36: LAB CIE
A37: 14 | I37: LAB CIE | N37: LAB CIE
A38: 15 | I38: LAB IA | N38: LAB IA
A39: 16 | I39: LAB IA | N39: LAB IA
A40: 17 | I40: CCE | N40: CCE
A41: 18
A42: 19
A43: 20
...

Sheet Evaluation
C1: PES Institute of Technology & Management, Shivamogga
C2: CO, PO & PSO Attainment Format
A4: Continous Internal Evaluation | D4: First Internal Assessment | V4: Second Internal Assessment | AN4: Remedial Test | BF4: SEE
A5: CO's | D5: =IF('Course Information'!$O$24="","",'Course Information'!$O$24) | E5: =IF('Course Information'!$O$25="","",'Course Information'!$O$25) | F5: =IF('Course Information'!$O$26="","",'Course Information'!$O$26) | G5: =IF('Course Information'!$O$27="","",'Course Information'!$O$27) | H5: =IF('Course Information'!$O$28="","",'Course Information'!$O$28) | I5: =IF('Course Information'!$O$29="","",'Course Information'!$O$29) | J5: =IF('Course Information'!$O$30="","",'Course Information'!$O$30) | K5: =IF('Course Information'!$O$31="","",'Course Information'!$O$31) | L5: =IF('Course Information'!$O$32="","",'Course Information'!$O$32) | M5: =IF('Course Information'!$O$33="","",'Course Information'!$O$33) | N5: =IF('Course Information'!$O$34="","",'Course Information'!$O$34) | O5: =IF('Course Information'!$O$35="","",'Course Information'!$O$35) | P5: =IF('Course Information'!$O$36="","",'Course Information'!$O$36) | Q5: =IF('Course Information'!$O$37="","",'Course Information'!$O$37) | R5: =IF('Course Information'!$O$38="","",'Course Information'!$O$38) | S5: =IF('Course Information'!$O$39="","",'Course Information'!$O$39) | T5: =IF('Course Information'!$O$40="","",'Course Information'!$O$40) | V5: =IF('Course Information'!$P$24="","",'Course Information'!$P$24) | W5: =IF('Course Information'!$P$25="","",'Course Information'!$P$25) | X5: =IF('Course Information'!$P$26="","",'Course Information'!$P$26) | Y5: =IF('Course Information'!$P$27="","",'Course Information'!$P$27) | Z5: =IF('Course Information'!$P$28="","",'Course Information'!$P$28) | AA5: =IF('Course Information'!$P$29="","",'Course Information'!$P$29) | AB5: =IF('Course Information'!$P$30="","",'Course Information'!$P$30) | AC5: =IF('Course Information'!$P$31="","",'Course Information'!$P$31) | AD5: =IF('Course Information'!$P$32="","",'Course Information'!$P$32) | AE5: =IF('Course Information'!$P$33="","",'Course Information'!$P$33) | AF5: =IF('Course Information'!$P$34="","",'Course Information'!$P$34) | AG5: =IF('Course Information'!$P$35="","",'Course Information'!$P$35) | AH5: =IF('Course Information'!$P$36="","",'Course Information'!$P$36) | AI5: =IF('Course Information'!$P$37="","",'Course Information'!$P$37) | AJ5: =IF('Course Information'!$P$38="","",'Course Information'!$P$38) | AK5: =IF('Course Information'!$P$39="","",'Course Information'!$P$39) | AL5: =IF('Course Information'!$P$40="","",'Course Information'!$P$40) | AN5: =IF('Course Information'!$Q$24="","",'Course Information'!$Q$24) -> RT1 | AW5: =IF('Course Information'!$Q$33="","",'Course Information'!$Q$33) -> RT2
A6: Question Number | D6: ='Course Information'!$I$24 -> 1a / 2a | E6: ='Course Information'!$I$25 -> 1b / 2b | F6: ='Course Information'!$I$26 -> 1c / 2c | G6: ='Course Information'!$I$27 -> 3a / 4a | H6: ='Course Information'!$I$28 -> 3b / 4b | I6: ='Course Information'!$I$29 -> 3c / 4c | J6: ='Course Information'!$I$30 -> 5a / 6a | K6: ='Course Information'!$I$31 -> 5b / 6b | L6: ='Course Information'!$I$32 -> 5c / 6c | M6: ='Course Information'!$I$33 -> 0 | N6: T-IA | O6: ='Course Information'!$I$35 -> 0 | P6: ='Course Information'!$I$36 -> LAB CIE | Q6: ='Course Information'!$I$37 -> LAB CIE | R6: ='Course Information'!$I$38 -> LAB IA | S6: ='Course Information'!$I$39 -> LAB IA | T6: ='Course Information'!$I$40 -> CCE | V6: ='Course Information'!$I$24 -> 1a / 2a | W6: ='Course Information'!$I$25 -> 1b / 2b | X6: ='Course Information'!$I$26 -> 1c / 2c | Y6: ='Course Information'!$I$27 -> 3a / 4a | Z6: ='Course Information'!$I$28 -> 3b / 4b | AA6: ='Course Information'!$I$29 -> 3c / 4c | AB6: ='Course Information'!$I$30 -> 5a / 6a | AC6: ='Course Information'!$I$31 -> 5b / 6b | AD6: ='Course Information'!$I$32 -> 5c / 6c | AE6: ='Course Information'!$I$33 -> 0 | AF6: T-IA | AG6: ='Course Information'!$I$35 -> 0 | AH6: ='Course Information'!$I$36 -> LAB CIE | AI6: ='Course Information'!$I$37 -> LAB CIE | AJ6: ='Course Information'!$I$38 -> LAB IA | AK6: ='Course Information'!$I$39 -> LAB IA | AL6: ='Course Information'!$I$40 -> CCE | AN6: ='Course Information'!$I$24 -> 1a / 2a | AO6: ='Course Information'!$I$25 -> 1b / 2b | AP6: ='Course Information'!$I$26 -> 1c / 2c | AQ6: ='Course Information'!$I$27 -> 3a / 4a | AR6: ='Course Information'!$I$28 -> 3b / 4b | AS6: ='Course Information'!$I$29 -> 3c / 4c | AW6: ='Course Information'!$I$24 -> 1a / 2a | AX6: ='Course Information'!$I$25 -> 1b / 2b | AY6: ='Course Information'!$I$26 -> 1c / 2c | AZ6: ='Course Information'!$I$27 -> 3a / 4a | BA6: ='Course Information'!$I$28 -> 3b / 4b | BB6: ='Course Information'!$I$29 -> 3c / 4c
B7: USN | C7: Name | D7: =IF('Course Information'!$J$24="","",'Course Information'!$J$24) | E7: =IF('Course Information'!$J$25="","",'Course Information'!$J$25) | F7: =IF('Course Information'!$J$26="","",'Course Information'!$J$26) | G7: =IF('Course Information'!$J$27="","",'Course Information'!$J$27) | H7: =IF('Course Information'!$J$28="","",'Course Information'!$J$28) | I7: =IF('Course Information'!$J$29="","",'Course Information'!$J$29) | J7: =IF('Course Information'!$J$30="","",'Course Information'!$J$30) | K7: =IF('Course Information'!$J$31="","",'Course Information'!$J$31) | L7: =IF('Course Information'!$J$32="","",'Course Information'!$J$32) | M7: =IF('Course Information'!$J$33="","",'Course Information'!$J$33) | N7: =IF('Course Information'!$J$34="","",'Course Information'!$J$34) | O7: =IF('Course Information'!$J$35="","",'Course Information'!$J$35) | P7: =IF('Course Information'!$J$36="","",'Course Information'!$J$36) | Q7: =IF('Course Information'!$J$37="","",'Course Information'!$J$37) | R7: =IF('Course Information'!$J$38="","",'Course Information'!$J$38) | S7: =IF('Course Information'!$J$39="","",'Course Information'!$J$39) | T7: =IF('Course Information'!$J$40="","",'Course Information'!$J$40) | V7: =IF('Course Information'!$K$24="","",'Course Information'!$K$24) | W7: =IF('Course Information'!$K$25="","",'Course Information'!$K$25) | X7: =IF('Course Information'!$K$26="","",'Course Information'!$K$26) | Y7: =IF('Course Information'!$K$27="","",'Course Information'!$K$27) | Z7: =IF('Course Information'!$K$28="","",'Course Information'!$K$28) | AA7: =IF('Course Information'!$K$29="","",'Course Information'!$K$29) | AB7: =IF('Course Information'!$K$30="","",'Course Information'!$K$30) | AC7: =IF('Course Information'!$K$31="","",'Course Information'!$K$31) | AD7: =IF('Course Information'!$K$32="","",'Course Information'!$K$32) | AE7: =IF('Course Information'!$K$33="","",'Course Information'!$K$33) | AF7: =IF('Course Information'!$K$34="","",'Course Information'!$K$34) | AG7: =IF('Course Information'!$K$35="","",'Course Information'!$K$35) | AH7: =IF('Course Information'!$K$36="","",'Course Information'!$K$36) | AI7: =IF('Course Information'!$K$37="","",'Course Information'!$K$37) | AJ7: =IF('Course Information'!$K$38="","",'Course Information'!$K$38) | AK7: =IF('Course Information'!$K$39="","",'Course Information'!$K$39) | AL7: =IF('Course Information'!$K$40="","",'Course Information'!$K$40) | AN7: =IF('Course Information'!$L$24="","",'Course Information'!$L$24) | AO7: =IF('Course Information'!$L$25="","",'Course Information'!$L$25) | AP7: =IF('Course Information'!$L$26="","",'Course Information'!$L$26) | AQ7: =IF('Course Information'!$L$27="","",'Course Information'!$L$27) | AR7: =IF('Course Information'!$L$28="","",'Course Information'!$L$28) | AS7: =IF('Course Information'!$L$29="","",'Course Information'!$L$29) | AT7: =IF('Course Information'!$L$30="","",'Course Information'!$L$30) | AU7: =IF('Course Information'!$L$31="","",'Course Information'!$L$31) | AV7: =IF('Course Information'!$L$32="","",'Course Information'!$L$32) -> RT2 | AW7: =IF('Course Information'!$L$33="","",'Course Information'!$L$33) | AX7: =IF('Course Information'!$L$34="","",'Course Information'!$L$34) | AY7: =IF('Course Information'!$L$35="","",'Course Information'!$L$35) | AZ7: =IF('Course Information'!$L$36="","",'Course Information'!$L$36) | BA7: =IF('Course Information'!$L$37="","",'Course Information'!$L$37) | BB7: =IF('Course Information'!$L$38="","",'Course Information'!$L$38) | BC7: =IF('Course Information'!$L$39="","",'Course Information'!$L$39) | BD7: =IF('Course Information'!$L$40="","",'Course Information'!$L$40) | BF7: ='Course Information'!N9 -> 50
A8: 1 | B8: ='Course Information'!B24 -> 0 | C8: ='Course Information'!D24 -> 0 | N8: =SUM(D8:L8) -> 0 | AF8: =SUM(V8:AD8) -> 0
A9: 2 | B9: ='Course Information'!B25 -> 0 | C9: ='Course Information'!D25 -> 0 | N9: =SUM(D9:L9) -> 0 | AF9: =SUM(V9:AD9) -> 0
A10: 3 | B10: ='Course Information'!B26 -> 0 | C10: ='Course Information'!D26 -> 0 | N10: =SUM(D10:L10) -> 0 | AF10: =SUM(V10:AD10) -> 0
A11: 4 | B11: ='Course Information'!B27 -> 0 | C11: ='Course Information'!D27 -> 0 | N11: =SUM(D11:L11) -> 0 | AF11: =SUM(V11:AD11) -> 0
A12: 5 | B12: ='Course Information'!B28 -> 0 | C12: ='Course Information'!D28 -> 0 | N12: =SUM(D12:L12) -> 0 | AF12: =SUM(V12:AD12) -> 0
A13: 6 | B13: ='Course Information'!B29 -> 0 | C13: ='Course Information'!D29 -> 0 | N13: =SUM(D13:L13) -> 0 | AF13: =SUM(V13:AD13) -> 0
A14: 7 | B14: ='Course Information'!B30 -> 0 | C14: ='Course Information'!D30 -> 0 | N14: =SUM(D14:L14) -> 0 | AF14: =SUM(V14:AD14) -> 0
A15: 8 | B15: ='Course Information'!B31 -> 0 | C15: ='Course Information'!D31 -> 0 | N15: =SUM(D15:L15) -> 0 | AF15: =SUM(V15:AD15) -> 0
A16: 9 | B16: ='Course Information'!B32 -> 0 | C16: ='Course Information'!D32 -> 0 | N16: =SUM(D16:L16) -> 0 | AF16: =SUM(V16:AD16) -> 0
A17: 10 | B17: ='Course Information'!B33 -> 0 | C17: ='Course Information'!D33 -> 0 | N17: =SUM(D17:L17) -> 0 | AF17: =SUM(V17:AD17) -> 0
A18: 11 | B18: ='Course Information'!B34 -> 0 | C18: ='Course Information'!D34 -> 0 | N18: =SUM(D18:L18) -> 0 | AF18: =SUM(V18:AD18) -> 0
A19: 12 | B19: ='Course Information'!B35 -> 0 | C19: ='Course Information'!D35 -> 0 | N19: =SUM(D19:L19) -> 0 | AF19: =SUM(V19:AD19) -> 0
... A82: 75 | B82: ='Course Information'!B98 -> 0 | C82: ='Course Information'!D98 -> 0 | N82: =SUM(D82:L82) -> 0 | AF82: =SUM(V82:AD82) -> 0
B84: Assessment Parameters | D84: Attainment Calculation - CIE 1 | V84: Attainment Calculation - CIE 2 | AN84: Attainment Calculation - CIE 3 | BF84: SEE
B85: CO's Mapped | D85: =D5 | E85: =E5 | F85: =F5 | G85: =G5 | H85: =H5 | I85: =I5 | J85: =J5 | K85: =K5 | ... T85: =T5 | V85: =V5 | W85: =W5 | X85: =X5 | Y85: =Y5 | Z85: =Z5 | AA85: =AA5 | AB85: =AB5 | AC85: =AC5 | ... AL85: =AL5 | AN85: =AN5 -> RT1 | AO85: =AO5 -> 0 | AP85: =AP5 -> 0 | AQ85: =AQ5 -> 0 | AR85: =AR5 -> 0 | AS85: =AS5 -> 0 | AT85: =AT5 -> 0 | AU85: =AU5 -> 0 | ... BD85: =BD5 -> 0
B86: Number of Participation | D86: =IF(COUNT(D8:D82)=0,"",COUNT(D8:D82)) | E86: =IF(COUNT(E8:E82)=0,"",COUNT(E8:E82)) | F86: =IF(COUNT(F8:F82)=0,"",COUNT(F8:F82)) | G86: =IF(COUNT(G8:G82)=0,"",COUNT(G8:G82)) | H86: =IF(COUNT(H8:H82)=0,"",COUNT(H8:H82)) | I86: =IF(COUNT(I8:I82)=0,"",COUNT(I8:I82)) | J86: =IF(COUNT(J8:J82)=0,"",COUNT(J8:J82)) | K86: =IF(COUNT(K8:K82)=0,"",COUNT(K8:K82)) | ... T86: =IF(COUNT(T8:T82)=0,"",COUNT(T8:T82)) | V86: =IF(COUNT(V8:V82)=0,"",COUNT(V8:V82)) | W86: =IF(COUNT(W8:W82)=0,"",COUNT(W8:W82)) | X86: =IF(COUNT(X8:X82)=0,"",COUNT(X8:X82)) | Y86: =IF(COUNT(Y8:Y82)=0,"",COUNT(Y8:Y82)) | Z86: =IF(COUNT(Z8:Z82)=0,"",COUNT(Z8:Z82)) | AA86: =IF(COUNT(AA8:AA82)=0,"",COUNT(AA8:AA82)) | AB86: =IF(COUNT(AB8:AB82)=0,"",COUNT(AB8:AB82)) | AC86: =IF(COUNT(AC8:AC82)=0,"",COUNT(AC8:AC82)) | ... AL86: =IF(COUNT(AL8:AL82)=0,"",COUNT(AL8:AL82)) | AN86: =IF(COUNT(AN8:AN82)=0,"",COUNT(AN8:AN82)) | AO86: =IF(COUNT(AO8:AO82)=0,"",COUNT(AO8:AO82)) | AP86: =IF(COUNT(AP8:AP82)=0,"",COUNT(AP8:AP82)) | AQ86: =IF(COUNT(AQ8:AQ82)=0,"",COUNT(AQ8:AQ82)) | AR86: =IF(COUNT(AR8:AR82)=0,"",COUNT(AR8:AR82)) | AS86: =IF(COUNT(AS8:AS82)=0,"",COUNT(AS8:AS82)) | AT86: =IF(COUNT(AT8:AT82)=0,"",COUNT(AT8:AT82)) | AU86: =IF(COUNT(AU8:AU82)=0,"",COUNT(AU8:AU82)) | ... BD86: =IF(COUNT(BD8:BD82)=0,"",COUNT(BD8:BD82)) | BF86: =IF(COUNT(BF8:BF82)=0,"",COUNT(BF8:BF82))
B87: Maximum Marks Alloted | D87: =D7 | E87: =E7 | F87: =F7 | G87: =G7 | H87: =H7 | I87: =I7 | J87: =J7 | K87: =K7 | ... T87: =T7 | V87: =V7 | W87: =W7 | X87: =X7 | Y87: =Y7 | Z87: =Z7 | AA87: =AA7 | AB87: =AB7 | AC87: =AC7 | ... AL87: =AL7 | AN87: =AN7 | AO87: =AO7 | AP87: =AP7 | AQ87: =AQ7 | AR87: =AR7 | AS87: =AS7 | AT87: =AT7 | AU87: =AU7 | AV87: =#REF! -> #REF! | AW87: =AV7 -> RT2 | AX87: =AX7 | AY87: =AY7 | AZ87: =AZ7 | BA87: =BA7 | BB87: =BB7 | BC87: =BC7 | BD87: =BD7 | BF87: ='Course Information'!N9 -> 50
B88: ='Course Information'!F9 -> 0 | C88: % of Alloted Marks | D88: =IFERROR(ROUNDDOWN(($B$88/100)*D87,0),"") | E88: =IFERROR(ROUNDDOWN(($B$88/100)*E87,0),"") | F88: =IFERROR(ROUNDDOWN(($B$88/100)*F87,0),"") | G88: =IFERROR(ROUNDDOWN(($B$88/100)*G87,0),"") | H88: =IFERROR(ROUNDDOWN(($B$88/100)*H87,0),"") | I88: =IFERROR(ROUNDDOWN(($B$88/100)*I87,0),"") | J88: =IFERROR(ROUNDDOWN(($B$88/100)*J87,0),"") | K88: =IFERROR(ROUNDDOWN(($B$88/100)*K87,0),"") | ... T88: =IFERROR(ROUNDDOWN(($B$88/100)*T87,0),"") | V88: =IFERROR(ROUNDDOWN(($B$88/100)*V87,0),"") | W88: =IFERROR(ROUNDDOWN(($B$88/100)*W87,0),"") | X88: =IFERROR(ROUNDDOWN(($B$88/100)*X87,0),"") | Y88: =IFERROR(ROUNDDOWN(($B$88/100)*Y87,0),"") | Z88: =IFERROR(ROUNDDOWN(($B$88/100)*Z87,0),"") | AA88: =IFERROR(ROUNDDOWN(($B$88/100)*AA87,0),"") | AB88: =IFERROR(ROUNDDOWN(($B$88/100)*AB87,0),"") | AC88: =IFERROR(ROUNDDOWN(($B$88/100)*AC87,0),"") | ... AL88: =IFERROR(ROUNDDOWN(($B$88/100)*AL87,0),"") | AN88: =IFERROR(ROUNDDOWN(($B$88/100)*AN87,0),"") | AO88: =IFERROR(ROUNDDOWN(($B$88/100)*AO87,0),"") | AP88: =IFERROR(ROUNDDOWN(($B$88/100)*AP87,0),"") | AQ88: =IFERROR(ROUNDDOWN(($B$88/100)*AQ87,0),"") | AR88: =IFERROR(ROUNDDOWN(($B$88/100)*AR87,0),"") | AS88: =IFERROR(ROUNDDOWN(($B$88/100)*AS87,0),"") | AT88: =IFERROR(ROUNDDOWN(($B$88/100)*AT87,0),"") | AU88: =IFERROR(ROUNDDOWN(($B$88/100)*AU87,0),"") | ... BD88: =IFERROR(ROUNDDOWN(($B$88/100)*BD87,0),"") | BF88: =IFERROR(ROUNDUP(($B$88/100)*BF87,0),"") -> 0
B89: Number of Students Scoring More than Target | D89: =IF(COUNTIF(D8:D82,">="&D88)=0,"NA",COUNTIF(D8:D82,">="&D88)) -> NA | E89: =IF(COUNTIF(E8:E82,">="&E88)=0,"NA",COUNTIF(E8:E82,">="&E88)) -> NA | F89: =IF(COUNTIF(F8:F82,">="&F88)=0,"NA",COUNTIF(F8:F82,">="&F88)) -> NA | G89: =IF(COUNTIF(G8:G82,">="&G88)=0,"NA",COUNTIF(G8:G82,">="&G88)) -> NA | H89: =IF(COUNTIF(H8:H82,">="&H88)=0,"NA",COUNTIF(H8:H82,">="&H88)) -> NA | I89: =IF(COUNTIF(I8:I82,">="&I88)=0,"NA",COUNTIF(I8:I82,">="&I88)) -> NA | J89: =IF(COUNTIF(J8:J82,">="&J88)=0,"NA",COUNTIF(J8:J82,">="&J88)) -> NA | K89: =IF(COUNTIF(K8:K82,">="&K88)=0,"NA",COUNTIF(K8:K82,">="&K88)) -> NA | ... T89: =IF(COUNTIF(T8:T82,">="&T88)=0,"NA",COUNTIF(T8:T82,">="&T88)) -> NA | V89: =IF(COUNTIF(V8:V82,">="&V88)=0,"NA",COUNTIF(V8:V82,">="&V88)) -> NA | W89: =IF(COUNTIF(W8:W82,">="&W88)=0,"NA",COUNTIF(W8:W82,">="&W88)) -> NA | X89: =IF(COUNTIF(X8:X82,">="&X88)=0,"NA",COUNTIF(X8:X82,">="&X88)) -> NA | Y89: =IF(COUNTIF(Y8:Y82,">="&Y88)=0,"NA",COUNTIF(Y8:Y82,">="&Y88)) -> NA | Z89: =IF(COUNTIF(Z8:Z82,">="&Z88)=0,"NA",COUNTIF(Z8:Z82,">="&Z88)) -> NA | AA89: =IF(COUNTIF(AA8:AA82,">="&AA88)=0,"NA",COUNTIF(AA8:AA82,">="&AA88)) -> NA | AB89: =IF(COUNTIF(AB8:AB82,">="&AB88)=0,"NA",COUNTIF(AB8:AB82,">="&AB88)) -> NA | AC89: =IF(COUNTIF(AC8:AC82,">="&AC88)=0,"NA",COUNTIF(AC8:AC82,">="&AC88)) -> NA | ... AL89: =IF(COUNTIF(AL8:AL82,">="&AL88)=0,"NA",COUNTIF(AL8:AL82,">="&AL88)) -> NA | AN89: =IF(COUNTIF(AN8:AN82,">="&AN88)=0,"NA",COUNTIF(AN8:AN82,">="&AN88)) -> NA | AO89: =IF(COUNTIF(AO8:AO82,">="&AO88)=0,"NA",COUNTIF(AO8:AO82,">="&AO88)) -> NA | AP89: =IF(COUNTIF(AP8:AP82,">="&AP88)=0,"NA",COUNTIF(AP8:AP82,">="&AP88)) -> NA | AQ89: =IF(COUNTIF(AQ8:AQ82,">="&AQ88)=0,"NA",COUNTIF(AQ8:AQ82,">="&AQ88)) -> NA | AR89: =IF(COUNTIF(AR8:AR82,">="&AR88)=0,"NA",COUNTIF(AR8:AR82,">="&AR88)) -> NA | AS89: =IF(COUNTIF(AS8:AS82,">="&AS88)=0,"NA",COUNTIF(AS8:AS82,">="&AS88)) -> NA | AT89: =IF(COUNTIF(AT8:AT82,">="&AT88)=0,"NA",COUNTIF(AT8:AT82,">="&AT88)) -> NA | AU89: =IF(COUNTIF(AU8:AU82,">="&AU88)=0,"NA",COUNTIF(AU8:AU82,">="&AU88)) -> NA | ... BD89: =IF(COUNTIF(BD8:BD82,">="&BD88)=0,"NA",COUNTIF(BD8:BD82,">="&BD88)) -> NA | BF89: =IF(COUNTIF(BF8:BF82,">="&BF88)=0,0,COUNTIF(BF8:BF82,">="&BF88)) -> 0
B90: Pecentage of Students Achieving Target | D90: =IFERROR(ROUNDUP((D89/D86)*100,0),"") | E90: =IFERROR(ROUNDUP((E89/E86)*100,0),"") | F90: =IFERROR(ROUNDUP((F89/F86)*100,0),"") | G90: =IFERROR(ROUNDUP((G89/G86)*100,0),"") | H90: =IFERROR(ROUNDUP((H89/H86)*100,0),"") | I90: =IFERROR(ROUNDUP((I89/I86)*100,0),"") | J90: =IFERROR(ROUNDUP((J89/J86)*100,0),"") | K90: =IFERROR(ROUNDUP((K89/K86)*100,0),"") | ... T90: =IFERROR(ROUNDUP((T89/T86)*100,0),"") | V90: =IFERROR(ROUNDUP((V89/V86)*100,0),"") | W90: =IFERROR(ROUNDUP((W89/W86)*100,0),"") | X90: =IFERROR(ROUNDUP((X89/X86)*100,0),"") | Y90: =IFERROR(ROUNDUP((Y89/Y86)*100,0),"") | Z90: =IFERROR(ROUNDUP((Z89/Z86)*100,0),"") | AA90: =IFERROR(ROUNDUP((AA89/AA86)*100,0),"") | AB90: =IFERROR(ROUNDUP((AB89/AB86)*100,0),"") | AC90: =IFERROR(ROUNDUP((AC89/AC86)*100,0),"") | ... AL90: =IFERROR(ROUNDUP((AL89/AL86)*100,0),"") | AN90: =IFERROR(ROUNDUP((AN89/AN86)*100,0),"") | AO90: =IFERROR(ROUNDUP((AO89/AO86)*100,0),"") | AP90: =IFERROR(ROUNDUP((AP89/AP86)*100,0),"") | AQ90: =IFERROR(ROUNDUP((AQ89/AQ86)*100,0),"") | AR90: =IFERROR(ROUNDUP((AR89/AR86)*100,0),"") | AS90: =IFERROR(ROUNDUP((AS89/AS86)*100,0),"") | AT90: =IFERROR(ROUNDUP((AT89/AT86)*100,0),"") | AU90: =IFERROR(ROUNDUP((AU89/AU86)*100,0),"") | ... BD90: =IFERROR(ROUNDUP((BD89/BD86)*100,0),"") | BF90: =IFERROR(ROUNDUP((BF89/BF86)*100,0),"")
C94: Course End Survey (on scale of 3) | D94: CO's | E94: IA 1 | F94: IA2 | G94: RT | H94: CCE | J94: AVG | L94: SEE | N94: Direct | P94: Indirect | R94: Total
D95: ='Course Information'!A13 -> CO.1 | E95: =IFERROR(SUMIF($D$85:$S$85,D96,$D$90:$S$90)/COUNTIF($D$85:$S$85,D96),"") | F95: =IFERROR(SUMIF($V$85:$AK$85,D95,$V$90:$AK$90)/COUNTIF($V$85:$AK$85,D95),"") | G95: =IFERROR(SUMIF($AN$85:$BC$85,D95,$AN$90:$BC$90)/COUNTIF($AN$85:$BC$85,D95),"") | H95: =IF($T$85=D95,$T$90,IF($AL$85=D95,$AL$90,IF($BD$85=D95,$BD$90,""))) | J95: =IFERROR(SUM(E95:H95)/(COUNT(E95:H95)),"") | L95: =$BF$90 | N95: =IFERROR(ROUNDUP((0.5*L95)+(0.5*J95),2),"") | P95: =IFERROR(ROUNDUP((C95/3)*100,2),"") -> 0 | R95: =IFERROR(ROUNDUP((0.8*N95)+(0.2*P95),2),"")
D96: ='Course Information'!A14 -> CO.2 | E96: =IFERROR(SUMIF($D$85:$S$85,D96,$D$90:$S$90)/COUNTIF($D$85:$S$85,D96),"") | F96: =IFERROR(SUMIF($V$85:$AK$85,D96,$V$90:$AK$90)/COUNTIF($V$85:$AK$85,D96),"") | G96: =IFERROR(SUMIF($AN$85:$BC$85,D96,$AN$90:$BC$90)/COUNTIF($AN$85:$BC$85,D96),"") | H96: =IF($T$85=D96,$T$90,IF($AL$85=D96,$AL$90,IF($BD$85=D96,$BD$90,""))) | J96: =IFERROR(SUM(E96:H96)/(COUNT(E96:H96)),"") | L96: =$BF$90 | N96: =IFERROR(ROUNDUP((0.5*L96)+(0.5*J96),2),"") | P96: =IFERROR(ROUNDUP((C96/3)*100,2),"") -> 0 | R96: =IFERROR(ROUNDUP((0.8*N96)+(0.2*P96),2),"")
D97: ='Course Information'!A15 -> CO.3 | E97: =IFERROR(SUMIF($D$85:$S$85,D97,$D$90:$S$90)/COUNTIF($D$85:$S$85,D97),"") | F97: =IFERROR(SUMIF($V$85:$AK$85,D97,$V$90:$AK$90)/COUNTIF($V$85:$AK$85,D97),"") | G97: =IFERROR(SUMIF($AN$85:$BC$85,D97,$AN$90:$BC$90)/COUNTIF($AN$85:$BC$85,D97),"") | H97: =IF($T$85=D97,$T$90,IF($AL$85=D97,$AL$90,IF($BD$85=D97,$BD$90,""))) | J97: =IFERROR(SUM(E97:H97)/(COUNT(E97:H97)),"") | L97: =$BF$90 | N97: =IFERROR(ROUNDUP((0.5*L97)+(0.5*J97),2),"") | P97: =IFERROR(ROUNDUP((C97/3)*100,2),"") -> 0 | R97: =IFERROR(ROUNDUP((0.8*N97)+(0.2*P97),2),"")
D98: ='Course Information'!A16 -> CO.4 | E98: =IFERROR(SUMIF($D$85:$S$85,D98,$D$90:$S$90)/COUNTIF($D$85:$S$85,D98),"") | F98: =IFERROR(SUMIF($V$85:$AK$85,D98,$V$90:$AK$90)/COUNTIF($V$85:$AK$85,D98),"") | G98: =IFERROR(SUMIF($AN$85:$BC$85,D98,$AN$90:$BC$90)/COUNTIF($AN$85:$BC$85,D98),"") | H98: =IF($T$85=D98,$T$90,IF($AL$85=D98,$AL$90,IF($BD$85=D98,$BD$90,""))) | J98: =IFERROR(SUM(E98:H98)/(COUNT(E98:H98)),"") | L98: =$BF$90 | N98: =IFERROR(ROUNDUP((0.5*L98)+(0.5*J98),2),"") | P98: =IFERROR(ROUNDUP((C98/3)*100,2),"") -> 0 | R98: =IFERROR(ROUNDUP((0.8*N98)+(0.2*P98),2),"")
D99: ='Course Information'!A17 -> CO.5 | E99: =IFERROR(SUMIF($D$85:$S$85,D99,$D$90:$S$90)/COUNTIF($D$85:$S$85,D99),"") | F99: =IFERROR(SUMIF($V$85:$AK$85,D99,$V$90:$AK$90)/COUNTIF($V$85:$AK$85,D99),"") | G99: =IFERROR(SUMIF($AN$85:$BC$85,D99,$AN$90:$BC$90)/COUNTIF($AN$85:$BC$85,D99),"") | H99: =IF($T$85=D99,$T$90,IF($AL$85=D99,$AL$90,IF($BD$85=D99,$BD$90,""))) | J99: =IFERROR(SUM(E99:H99)/(COUNT(E99:H99)),"") | L99: =$BF$90 | N99: =IFERROR(ROUNDUP((0.5*L99)+(0.5*J99),2),"") | P99: =IFERROR(ROUNDUP((C99/3)*100,2),"") -> 0 | R99: =IFERROR(ROUNDUP((0.8*N99)+(0.2*P99),2),"")
D100: ='Course Information'!A18 -> CO.6 | E100: =IFERROR(SUMIF($D$85:$S$85,D100,$D$90:$S$90)/COUNTIF($D$85:$S$85,D100),"") | F100: =IFERROR(SUMIF($V$85:$AK$85,D100,$V$90:$AK$90)/COUNTIF($V$85:$AK$85,D100),"") | G100: =IFERROR(SUMIF($AN$85:$BC$85,D100,$AN$90:$BC$90)/COUNTIF($AN$85:$BC$85,D100),"") | H100: =IF($T$85=D100,$T$90,IF($AL$85=D100,$AL$90,IF($BD$85=D100,$BD$90,""))) | J100: =IFERROR(SUM(E100:H100)/(COUNT(E100:H100)),"") | L100: =$BF$90 | N100: =IFERROR(ROUNDUP((0.5*L100)+(0.5*J100),2),"") | P100: =IFERROR(ROUNDUP((C100/3)*100,2),"") -> 0 | R100: =IFERROR(ROUNDUP((0.8*N100)+(0.2*P100),2),"")

Sheet IA1 Attainment
B1: PES Institute of Technology & Management, Shivamogga
B2: ='Course Information'!N4 -> Information Science & Engg
B3: Course Outcome Attainment in 1st IA
A4: Course Name | D4: ='Course Information'!$F$6 -> DATA STRUCTURE AND APPLICATIONS
A5: Course Code | D5: ='Course Information'!$F$7 -> 1BCS305 | F5: NBA Code | H5: ='Course Information'!$N$7 -> 0
A6: Academic Year | D6: ='Course Information'!$F$5 -> 2026-27 | F6: No. of Students | H6: ='Course Information'!$N$6 -> 57
A8: CO's | B8: Attainment through Test | D8: Attainment through CCE | F8: Total Attainment | H8: Remarks
A9: ='Course Information'!$A$13:$B$13 -> CO.1 | B9: =Evaluation!E95 | D9: =Evaluation!H95 | F9: =IFERROR(SUM(B9:E9)/COUNT(B9:E9),"") | H9: =IF(F9="","",IF(F9>65,"Complete Attainment",IF(F9>60,"Moderate Attainment",IF(F9>55,"Poor Attainment",IF(F9<55,"Not Attained","")))))
A10: ='Course Information'!$A$14:$B$14 -> CO.2 | B10: =Evaluation!E96 | D10: =Evaluation!H96 | F10: =IFERROR(SUM(B10:E10)/COUNT(B10:E10),"") | H10: =IF(F10="","",IF(F10>65,"Complete Attainment",IF(F10>60,"Moderate Attainment",IF(F10>55,"Poor Attainment",IF(F10<55,"Not Attained","")))))
A11: ='Course Information'!$A$15:$B$15 -> CO.3 | B11: =Evaluation!E97 | D11: =Evaluation!H97 | F11: =IFERROR(SUM(B11:E11)/COUNT(B11:E11),"") | H11: =IF(F11="","",IF(F11>65,"Complete Attainment",IF(F11>60,"Moderate Attainment",IF(F11>55,"Poor Attainment",IF(F11<55,"Not Attained","")))))
A12: ='Course Information'!$A$16:$B$16 -> CO.4 | B12: =Evaluation!E98 | D12: =Evaluation!H98 | F12: =IFERROR(SUM(B12:E12)/COUNT(B12:E12),"") | H12: =IF(F12="","",IF(F12>65,"Complete Attainment",IF(F12>60,"Moderate Attainment",IF(F12>55,"Poor Attainment",IF(F12<55,"Not Attained","")))))
A13: ='Course Information'!$A$17:$B$17 -> CO.5 | B13: =Evaluation!E99 | D13: =Evaluation!H99 | F13: =IFERROR(SUM(B13:E13)/COUNT(B13:E13),"") | H13: =IF(F13="","",IF(F13>65,"Complete Attainment",IF(F13>60,"Moderate Attainment",IF(F13>55,"Poor Attainment",IF(F13<55,"Not Attained","")))))
A14: ='Course Information'!$A$18:$B$18 -> CO.6 | B14: =Evaluation!E100 | D14: =Evaluation!H100 | F14: =IFERROR(SUM(B14:E14)/COUNT(B14:E14),"") | H14: =IF(F14="","",IF(F14>65,"Complete Attainment",IF(F14>60,"Moderate Attainment",IF(F14>55,"Poor Attainment",IF(F14<55,"Not Attained","")))))
A18: ='Course Information'!F8 -> Thara K L | F18: ='Course Information'!N8 -> 0
A19: Course Instructor | F19: Head of the Department

Sheet IA2 Attainment
B1: PES Institute of Technology & Management, Shivamogga
B2: ='Course Information'!N4 -> Information Science & Engg
B3: Course Outcome Attainment in 2nd IA
A4: Course Name | D4: ='Course Information'!$F$6 -> DATA STRUCTURE AND APPLICATIONS
A5: Course Code | D5: ='Course Information'!$F$7 -> 1BCS305 | F5: NBA Code | H5: ='Course Information'!$N$7 -> 0
A6: Academic Year | D6: ='Course Information'!$F$5 -> 2026-27 | F6: No. of Students | H6: ='Course Information'!$N$6 -> 57
A8: CO's | B8: Attainment through Test | D8: Attainment through CCE | F8: Total Attainment | H8: Remarks
A9: ='Course Information'!$A$13:$B$13 -> CO.1 | B9: =Evaluation!F95 | D9: NA | F9: =IFERROR(SUM(B9:E9)/COUNT(B9:E9),"") | H9: =IF(F9="","",IF(F9>65,"Complete Attainment",IF(F9>60,"Moderate Attainment",IF(F9>55,"Poor Attainment",IF(F9<55,"Not Attained","")))))
A10: ='Course Information'!$A$14:$B$14 -> CO.2 | B10: =Evaluation!F96 | D10: NA | F10: =IFERROR(SUM(B10:E10)/COUNT(B10:E10),"") | H10: =IF(F10="","",IF(F10>65,"Complete Attainment",IF(F10>60,"Moderate Attainment",IF(F10>55,"Poor Attainment",IF(F10<55,"Not Attained","")))))
A11: ='Course Information'!$A$15:$B$15 -> CO.3 | B11: =Evaluation!F97 | D11: NA | F11: =IFERROR(SUM(B11:E11)/COUNT(B11:E11),"") | H11: =IF(F11="","",IF(F11>65,"Complete Attainment",IF(F11>60,"Moderate Attainment",IF(F11>55,"Poor Attainment",IF(F11<55,"Not Attained","")))))
A12: ='Course Information'!$A$16:$B$16 -> CO.4 | B12: =Evaluation!F98 | D12: NA | F12: =IFERROR(SUM(B12:E12)/COUNT(B12:E12),"") | H12: =IF(F12="","",IF(F12>65,"Complete Attainment",IF(F12>60,"Moderate Attainment",IF(F12>55,"Poor Attainment",IF(F12<55,"Not Attained","")))))
A13: ='Course Information'!$A$17:$B$17 -> CO.5 | B13: =Evaluation!F99 | D13: NA | F13: =IFERROR(SUM(B13:E13)/COUNT(B13:E13),"") | H13: =IF(F13="","",IF(F13>65,"Complete Attainment",IF(F13>60,"Moderate Attainment",IF(F13>55,"Poor Attainment",IF(F13<55,"Not Attained","")))))
A14: ='Course Information'!$A$18:$B$18 -> CO.6 | B14: =Evaluation!F100 | D14: NA | F14: =IFERROR(SUM(B14:E14)/COUNT(B14:E14),"") | H14: =IF(F14="","",IF(F14>65,"Complete Attainment",IF(F14>60,"Moderate Attainment",IF(F14>55,"Poor Attainment",IF(F14<55,"Not Attained","")))))
A18: ='Course Information'!F8 -> Thara K L | F18: ='Course Information'!N8 -> 0
A19: Course Instructor | F19: Head of the Department

Sheet Overall Attainment
A1: PES Institute of Technology & Management, Shivamogga NH-206, SAGAR ROAD, SHIVAMOGGA - 577204
A2: PESITM - IQAC - Form 10B / R0 – Attainments
A3: ='Course Information'!N4 -> Information Science & Engg
B4: Course Outcome Attainment
A5: Course Name | D5: ='Course Information'!$F$6 -> DATA STRUCTURE AND APPLICATIONS
A6: Course Code | D6: ='Course Information'!$F$7 -> 1BCS305 | F6: NBA Code | H6: ='Course Information'!$N$7 -> 0
A7: Academic Year | D7: ='Course Information'!$F$5 -> 2026-27 | F7: No. of Students | H7: ='Course Information'!$N$6 -> 57
A9: CO's | B9: Direct Attainment | D9: Indirect Attainment | F9: Total Attainment | H9: Remarks
A10: ='Course Information'!$A$13:$B$13 -> CO.1 | B10: =Evaluation!N95 | D10: =Evaluation!P95 -> 0 | F10: =Evaluation!R95 | H10: =IF(F10="","",IF(F10>65,"Complete Attainment",IF(F10>60,"Moderate Attainment",IF(F10>55,"Poor Attainment",IF(F10<55,"Not Attained","")))))
A11: ='Course Information'!$A$14:$B$14 -> CO.2 | B11: =Evaluation!N96 | D11: =Evaluation!P96 -> 0 | F11: =Evaluation!R96 | H11: =IF(F11="","",IF(F11>65,"Complete Attainment",IF(F11>60,"Moderate Attainment",IF(F11>55,"Poor Attainment",IF(F11<55,"Not Attained","")))))
A12: ='Course Information'!$A$15:$B$15 -> CO.3 | B12: =Evaluation!N97 | D12: =Evaluation!P97 -> 0 | F12: =Evaluation!R97 | H12: =IF(F12="","",IF(F12>65,"Complete Attainment",IF(F12>60,"Moderate Attainment",IF(F12>55,"Poor Attainment",IF(F12<55,"Not Attained","")))))
A13: ='Course Information'!$A$16:$B$16 -> CO.4 | B13: =Evaluation!N98 | D13: =Evaluation!P98 -> 0 | F13: =Evaluation!R98 | H13: =IF(F13="","",IF(F13>65,"Complete Attainment",IF(F13>60,"Moderate Attainment",IF(F13>55,"Poor Attainment",IF(F13<55,"Not Attained","")))))
A14: ='Course Information'!$A$17:$B$17 -> CO.5 | B14: =Evaluation!N99 | D14: =Evaluation!P99 -> 0 | F14: =Evaluation!R99 | H14: =IF(F14="","",IF(F14>65,"Complete Attainment",IF(F14>60,"Moderate Attainment",IF(F14>55,"Poor Attainment",IF(F14<55,"Not Attained","")))))
A15: ='Course Information'!$A$18:$B$18 -> CO.6 | B15: =Evaluation!N100 | D15: =Evaluation!P100 -> 0 | F15: =Evaluation!R100 | H15: =IF(F15="","",IF(F15>65,"Complete Attainment",IF(F15>60,"Moderate Attainment",IF(F15>55,"Poor Attainment",IF(F15<55,"Not Attained","")))))
A35: ='Course Information'!F8 -> Thara K L | F35: ='Course Information'!N8 -> 0
A36: Course Instructor | F36: Head of the Department
B40: PES Institute of Technology & Management, Shivamogga
B41: ='Course Information'!N4 -> Information Science & Engg
B42: Program Outcome Attainment
A43: Course Name | D43: ='Course Information'!$F$6 -> DATA STRUCTURE AND APPLICATIONS
A44: Course Code | D44: ='Course Information'!$F$7 -> 1BCS305 | F44: NBA Code | H44: ='Course Information'!$N$7 -> 0
A45: Academic Year | D45: ='Course Information'!$F$5 -> 2026-27 | F45: No. of Students | H45: ='Course Information'!$N$6 -> 57
A48: PO's | B48: Achievable | D48: Attained | F48: Percentage | H48: Remarks
A49: PO1 | B49: ='Course Information'!C19 -> NA | D49: =IFERROR(ROUNDUP(('Course Information'!C19/100)*(SUM($F$10*'Course Information'!C13,$F$11*'Course Information'!C14,$F$12*'Course Information'!C15,$F$13*'Course Information'!C16,$F$14*'Course Information'!C17,$F$15*'Course Information'!C18))/SUM('Course Information'!C13:C18),2),"") | F49: =IFERROR(ROUNDUP((D49/B49)*100,2),"") | H49: =IF(F49="","",IF(F49>75,"Attained","Not Attained"))
A50: PO2 | B50: ='Course Information'!D19 -> NA | D50: =IFERROR(ROUNDUP(('Course Information'!D19/100)*(SUM($F$10*'Course Information'!D13,$F$11*'Course Information'!D14,$F$12*'Course Information'!D15,$F$13*'Course Information'!D16,$F$14*'Course Information'!D17,$F$15*'Course Information'!D18))/SUM('Course Information'!D13:D18),2),"") | F50: =IFERROR(ROUNDUP((D50/B50)*100,2),"") | H50: =IF(F50="","",IF(F50>75,"Attained","Not Attained"))
A51: PO3 | B51: ='Course Information'!E19 -> NA | D51: =IFERROR(ROUNDUP(('Course Information'!E19/100)*(SUM($F$10*'Course Information'!E13,$F$11*'Course Information'!E14,$F$12*'Course Information'!E15,$F$13*'Course Information'!E16,$F$14*'Course Information'!E17,$F$15*'Course Information'!E18))/SUM('Course Information'!E13:E18),2),"") | F51: =IFERROR(ROUNDUP((D51/B51)*100,2),"") | H51: =IF(F51="","",IF(F51>75,"Attained","Not Attained"))
A52: PO4 | B52: ='Course Information'!F19 -> NA | D52: =IFERROR(ROUNDUP(('Course Information'!F19/100)*(SUM($F$10*'Course Information'!F13,$F$11*'Course Information'!F14,$F$12*'Course Information'!F15,$F$13*'Course Information'!F16,$F$14*'Course Information'!F17,$F$15*'Course Information'!F18))/SUM('Course Information'!F13:F18),2),"") | F52: =IFERROR(ROUNDUP((D52/B52)*100,2),"") | H52: =IF(F52="","",IF(F52>75,"Attained","Not Attained"))
A53: PO5 | B53: ='Course Information'!G19 -> NA | D53: =IFERROR(ROUNDUP(('Course Information'!G19/100)*(SUM($F$10*'Course Information'!G13,$F$11*'Course Information'!G14,$F$12*'Course Information'!G15,$F$13*'Course Information'!G16,$F$14*'Course Information'!G17,$F$15*'Course Information'!G18))/SUM('Course Information'!G13:G18),2),"") | F53: =IFERROR(ROUNDUP((D53/B53)*100,2),"") | H53: =IF(F53="","",IF(F53>75,"Attained","Not Attained"))
A54: PO6 | B54: ='Course Information'!H19 -> NA | D54: =IFERROR(ROUNDUP(('Course Information'!H19/100)*(SUM($F$10*'Course Information'!H13,$F$11*'Course Information'!H14,$F$12*'Course Information'!H15,$F$13*'Course Information'!H16,$F$14*'Course Information'!H17,$F$15*'Course Information'!H18))/SUM('Course Information'!H13:H18),2),"") | F54: =IFERROR(ROUNDUP((D54/B54)*100,2),"") | H54: =IF(F54="","",IF(F54>75,"Attained","Not Attained"))
A55: PO7 | B55: ='Course Information'!I19 -> NA | D55: =IFERROR(ROUNDUP(('Course Information'!I19/100)*(SUM($F$10*'Course Information'!I13,$F$11*'Course Information'!I14,$F$12*'Course Information'!I15,$F$13*'Course Information'!I16,$F$14*'Course Information'!I17,$F$15*'Course Information'!I18))/SUM('Course Information'!I13:I18),2),"") | F55: =IFERROR(ROUNDUP((D55/B55)*100,2),"") | H55: =IF(F55="","",IF(F55>75,"Attained","Not Attained"))
A56: PO8 | B56: ='Course Information'!J19 -> NA | D56: =IFERROR(ROUNDUP(('Course Information'!J19/100)*(SUM($F$10*'Course Information'!J13,$F$11*'Course Information'!J14,$F$12*'Course Information'!J15,$F$13*'Course Information'!J16,$F$14*'Course Information'!J17,$F$15*'Course Information'!J18))/SUM('Course Information'!J13:J18),2),"") | F56: =IFERROR(ROUNDUP((D56/B56)*100,2),"") | H56: =IF(F56="","",IF(F56>75,"Attained","Not Attained"))
A57: PO9 | B57: ='Course Information'!K19 -> NA | D57: =IFERROR(ROUNDUP(('Course Information'!K19/100)*(SUM($F$10*'Course Information'!K13,$F$11*'Course Information'!K14,$F$12*'Course Information'!K15,$F$13*'Course Information'!K16,$F$14*'Course Information'!K17,$F$15*'Course Information'!K18))/SUM('Course Information'!K13:K18),2),"") | F57: =IFERROR(ROUNDUP((D57/B57)*100,2),"") | H57: =IF(F57="","",IF(F57>75,"Attained","Not Attained"))
A58: PO10 | B58: ='Course Information'!L19 -> NA | D58: =IFERROR(ROUNDUP(('Course Information'!L19/100)*(SUM($F$10*'Course Information'!L13,$F$11*'Course Information'!L14,$F$12*'Course Information'!L15,$F$13*'Course Information'!L16,$F$14*'Course Information'!L17,$F$15*'Course Information'!L18))/SUM('Course Information'!L13:L18),2),"") | F58: =IFERROR(ROUNDUP((D58/B58)*100,2),"") | H58: =IF(F58="","",IF(F58>75,"Attained","Not Attained"))
A59: PO11 | B59: ='Course Information'!M19 -> NA | D59: =IFERROR(ROUNDUP(('Course Information'!M19/100)*(SUM($F$10*'Course Information'!M13,$F$11*'Course Information'!M14,$F$12*'Course Information'!M15,$F$13*'Course Information'!M16,$F$14*'Course Information'!M17,$F$15*'Course Information'!M18))/SUM('Course Information'!M13:M18),2),"") | F59: =IFERROR(ROUNDUP((D59/B59)*100,2),"") | H59: =IF(F59="","",IF(F59>75,"Attained","Not Attained"))
A60: PO12 | B60: ='Course Information'!N19 -> NA | D60: =IFERROR(ROUNDUP(('Course Information'!N19/100)*(SUM($F$10*'Course Information'!N13,$F$11*'Course Information'!N14,$F$12*'Course Information'!N15,$F$13*'Course Information'!N16,$F$14*'Course Information'!N17,$F$15*'Course Information'!N18))/SUM('Course Information'!N13:N18),2),"") | F60: =IFERROR(ROUNDUP((D60/B60)*100,2),"") | H60: =IF(F60="","",IF(F60>75,"Attained","Not Attained"))
A80: ='Course Information'!F8 -> Thara K L | F80: ='Course Information'!N8 -> 0
A81: Course Instructor | F81: Head of the Department
B83: PES Institute of Technology & Management, Shivamogga
B84: ='Course Information'!N4 -> Information Science & Engg
B85: Program Specific Outcome Attainment
...

Sheet Course Closure Report
A1: PES Institute of Technology & Management, Shivamogga NH-206, SAGAR ROAD, SHIVAMOGGA - 577204
A2: Semester
A3: PESITM - IQAC - Form 10C / R0 – Course Closure Report
A4: ='Course Information'!N4 -> Information Science & Engg
A5: Course Name | D5: ='Course Information'!$F$6 -> DATA STRUCTURE AND APPLICATIONS
A6: Course Code | D6: ='Course Information'!$F$7 -> 1BCS305 | F6: NBA Code | H6: ='Course Information'!$N$7 -> 0
A7: Academic Year | D7: ='Course Information'!$F$5 -> 2026-27 | F7: Course Target | H7: ='Course Information'!$F$9 -> 0
A8: CO's | F8: CO Attainment Through CIE | H8: CO Attainment Through SEE
F9: =Evaluation!J95 | H9: =Evaluation!L95
F10: =Evaluation!J96
F11: =Evaluation!J97
F12: =Evaluation!J98
F13: =Evaluation!J99
F14: =Evaluation!J100
A15: Program Outcomes | D15: Achievable | F15: Attained | H15: Percentage
A16: PO1 | D16: ='Overall Attainment'!B49 -> NA | F16: ='Overall Attainment'!D49 | H16: ='Overall Attainment'!F49
A17: PO2 | D17: ='Overall Attainment'!B50 -> NA | F17: ='Overall Attainment'!D50 | H17: ='Overall Attainment'!F50
A18: PO3 | D18: ='Overall Attainment'!B51 -> NA | F18: ='Overall Attainment'!D51 | H18: ='Overall Attainment'!F51
A19: PO4 | D19: ='Overall Attainment'!B52 -> NA | F19: ='Overall Attainment'!D52 | H19: ='Overall Attainment'!F52
A20: PO5 | D20: ='Overall Attainment'!B53 -> NA | F20: ='Overall Attainment'!D53 | H20: ='Overall Attainment'!F53
A21: PO6 | D21: ='Overall Attainment'!B54 -> NA | F21: ='Overall Attainment'!D54 | H21: ='Overall Attainment'!F54
A22: PO7 | D22: ='Overall Attainment'!B55 -> NA | F22: ='Overall Attainment'!D55 | H22: ='Overall Attainment'!F55
A23: PO8 | D23: ='Overall Attainment'!B56 -> NA | F23: ='Overall Attainment'!D56 | H23: ='Overall Attainment'!F56
A24: PO9 | D24: ='Overall Attainment'!B57 -> NA | F24: ='Overall Attainment'!D57 | H24: ='Overall Attainment'!F57
A25: PO10 | D25: ='Overall Attainment'!B58 -> NA | F25: ='Overall Attainment'!D58 | H25: ='Overall Attainment'!F58
A26: PO11 | D26: ='Overall Attainment'!B59 -> NA | F26: ='Overall Attainment'!D59 | H26: ='Overall Attainment'!F59
A27: PO12 | D27: ='Overall Attainment'!B60 -> NA | F27: ='Overall Attainment'!D60 | H27: ='Overall Attainment'!F60
A28: Program Specific Outcomes | D28: Achievable | F28: Attained | H28: Percentage
A29: PSO1 | D29: ='Overall Attainment'!B92 -> NA | F29: ='Overall Attainment'!D92 | H29: ='Overall Attainment'!F92
A30: PSO2 | D30: ='Overall Attainment'!B93 -> NA | F30: ='Overall Attainment'!D93 | H30: ='Overall Attainment'!F93
A31: PSO3 | D31: ='Overall Attainment'!B94 -> NA | F31: ='Overall Attainment'!D94 | H31: ='Overall Attainment'!F94
A32: Remarks by Course Instructor:
A39: ='Course Information'!F8 -> Thara K L | F39: ='Course Information'!N8 -> 0
A40: Course Instructor | F40: Head of the Department

Sheet IA1 Summary
A1: PES INSTITUTE OF TECHNOLOGY & MANAGEMENT
A2: NH-206, SAGAR ROAD, SHIVAMOGGA - 577204
A3: ='Course Information'!$N$4 -> Information Science & Engg
A4: Academic Year: | C4: ='Course Information'!$F$5 -> 2026-27
A5: Semester: | B5: ='Course Information'!N5 -> III | C5: Section: | D5: ='Course Information'!P5 -> A
A6: Course: | B6: ='Course Information'!$F$6 -> DATA STRUCTURE AND APPLICATIONS | E6: Course Code: | F6: ='Course Information'!$F$7 -> 1BCS305
A7: Course Instructor: | C7: ='Course Information'!F8 -> Thara K L
A8: Attendance Status & | D8: IA Marks
A9: Sl. No. | B9: USN | C9: Name of the Student | D9: NCC | E9: 19
D10: NCA | E10: Attendance % | F10: IA Marks
A11: 1 | B11: ='Course Information'!B24 -> 0 | C11: ='Course Information'!D24 -> 0 | E11: =IFERROR(ROUNDUP((D11/$E$9)*100,0),"") -> 0 | F11: =Evaluation!N8 -> 0
A12: 2 | B12: ='Course Information'!B25 -> 0 | C12: ='Course Information'!D25 -> 0 | E12: =IFERROR(ROUNDUP((D12/$E$9)*100,0),"") -> 0 | F12: =Evaluation!N9 -> 0
A13: 3 | B13: ='Course Information'!B26 -> 0 | C13: ='Course Information'!D26 -> 0 | E13: =IFERROR(ROUNDUP((D13/$E$9)*100,0),"") -> 0 | F13: =Evaluation!N10 -> 0
A14: 4 | B14: ='Course Information'!B27 -> 0 | C14: ='Course Information'!D27 -> 0 | E14: =IFERROR(ROUNDUP((D14/$E$9)*100,0),"") -> 0 | F14: =Evaluation!N11 -> 0
A15: 5 | B15: ='Course Information'!B28 -> 0 | C15: ='Course Information'!D28 -> 0 | E15: =IFERROR(ROUNDUP((D15/$E$9)*100,0),"") -> 0 | F15: =Evaluation!N12 -> 0
A16: 6 | B16: ='Course Information'!B29 -> 0 | C16: ='Course Information'!D29 -> 0 | E16: =IFERROR(ROUNDUP((D16/$E$9)*100,0),"") -> 0 | F16: =Evaluation!N13 -> 0
A17: 7 | B17: ='Course Information'!B30 -> 0 | C17: ='Course Information'!D30 -> 0 | E17: =IFERROR(ROUNDUP((D17/$E$9)*100,0),"") -> 0 | F17: =Evaluation!N14 -> 0
A18: 8 | B18: ='Course Information'!B31 -> 0 | C18: ='Course Information'!D31 -> 0 | E18: =IFERROR(ROUNDUP((D18/$E$9)*100,0),"") -> 0 | F18: =Evaluation!N15 -> 0
A19: 9 | B19: ='Course Information'!B32 -> 0 | C19: ='Course Information'!D32 -> 0 | E19: =IFERROR(ROUNDUP((D19/$E$9)*100,0),"") -> 0 | F19: =Evaluation!N16 -> 0
A20: 10 | B20: ='Course Information'!B33 -> 0 | C20: ='Course Information'!D33 -> 0 | E20: =IFERROR(ROUNDUP((D20/$E$9)*100,0),"") -> 0 | F20: =Evaluation!N17 -> 0
A21: 11 | B21: ='Course Information'!B34 -> 0 | C21: ='Course Information'!D34 -> 0 | E21: =IFERROR(ROUNDUP((D21/$E$9)*100,0),"") -> 0 | F21: =Evaluation!N18 -> 0
A22: 12 | B22: ='Course Information'!B35 -> 0 | C22: ='Course Information'!D35 -> 0 | E22: =IFERROR(ROUNDUP((D22/$E$9)*100,0),"") -> 0 | F22: =Evaluation!N19 -> 0
... A76: 66 | B76: ='Course Information'!B89 -> 0 | C76: ='Course Information'!D89 -> 0 | E76: =IFERROR(ROUNDUP((D76/$E$9)*100,0),"") -> 0 | F76: =Evaluation!N73 -> 0
A77: Total Number of Students | E77: =COUNTA('[1]Student List'!B7:B96) -> 90
A78: Number of Absentees | E78: =COUNTIF(F11:F76,"AB") -> 0
A79: Number of Students Scoring Between 0 & 20 | E79: =COUNTIF(F11:F76,"<=20") -> 66
A80: Number of Students Scoring Between 21 & 40 | E80: =COUNTIF(F11:F76,"<=40")-E79 -> 0
A81: Number of Students Scoring Between 41 & 50 | E81: =COUNTIF(F11:F76,">=41") -> 0
A82: Number of Students with Less than 85% Attendance | E82: =COUNTIF(E11:E76,"<85") -> 66
A86: (Signature of Course Instructor) (Signature of the HOD)

Sheet IA2 Summary
A1: PES INSTITUTE OF TECHNOLOGY & MANAGEMENT
A2: NH-206, SAGAR ROAD, SHIVAMOGGA - 577204
A3: ='Course Information'!$N$4 -> Information Science & Engg
A4: Academic Year: | C4: ='Course Information'!$F$5 -> 2026-27
A5: Semester: | B5: ='Course Information'!N5 -> III | C5: Section: | D5: ='Course Information'!P5 -> A
A6: Course: | B6: ='Course Information'!$F$6 -> DATA STRUCTURE AND APPLICATIONS | E6: Course Code: | F6: ='Course Information'!$F$7 -> 1BCS305
A7: Course Instructor: | C7: ='Course Information'!F8 -> Thara K L
A8: Attendance Status & | D8: IA Marks
A9: Sl. No. | B9: USN | C9: Name of the Student | D9: NCC | E9: 19
D10: NCA | E10: Attendance % | F10: IA Marks
A11: 1 | B11: ='Course Information'!B24 -> 0 | C11: ='Course Information'!D24 -> 0 | E11: =IFERROR(ROUNDUP((D11/$E$9)*100,0),"") -> 0 | F11: =Evaluation!AF8 -> 0
A12: 2 | B12: ='Course Information'!B25 -> 0 | C12: ='Course Information'!D25 -> 0 | E12: =IFERROR(ROUNDUP((D12/$E$9)*100,0),"") -> 0 | F12: =Evaluation!AF9 -> 0
A13: 3 | B13: ='Course Information'!B26 -> 0 | C13: ='Course Information'!D26 -> 0 | E13: =IFERROR(ROUNDUP((D13/$E$9)*100,0),"") -> 0 | F13: =Evaluation!AF10 -> 0
A14: 4 | B14: ='Course Information'!B27 -> 0 | C14: ='Course Information'!D27 -> 0 | E14: =IFERROR(ROUNDUP((D14/$E$9)*100,0),"") -> 0 | F14: =Evaluation!AF11 -> 0
A15: 5 | B15: ='Course Information'!B28 -> 0 | C15: ='Course Information'!D28 -> 0 | E15: =IFERROR(ROUNDUP((D15/$E$9)*100,0),"") -> 0 | F15: =Evaluation!AF12 -> 0
A16: 6 | B16: ='Course Information'!B29 -> 0 | C16: ='Course Information'!D29 -> 0 | E16: =IFERROR(ROUNDUP((D16/$E$9)*100,0),"") -> 0 | F16: =Evaluation!AF13 -> 0
A17: 7 | B17: ='Course Information'!B30 -> 0 | C17: ='Course Information'!D30 -> 0 | E17: =IFERROR(ROUNDUP((D17/$E$9)*100,0),"") -> 0 | F17: =Evaluation!AF14 -> 0
A18: 8 | B18: ='Course Information'!B31 -> 0 | C18: ='Course Information'!D31 -> 0 | E18: =IFERROR(ROUNDUP((D18/$E$9)*100,0),"") -> 0 | F18: =Evaluation!AF15 -> 0
A19: 9 | B19: ='Course Information'!B32 -> 0 | C19: ='Course Information'!D32 -> 0 | E19: =IFERROR(ROUNDUP((D19/$E$9)*100,0),"") -> 0 | F19: =Evaluation!AF16 -> 0
A20: 10 | B20: ='Course Information'!B33 -> 0 | C20: ='Course Information'!D33 -> 0 | E20: =IFERROR(ROUNDUP((D20/$E$9)*100,0),"") -> 0 | F20: =Evaluation!AF17 -> 0
A21: 11 | B21: ='Course Information'!B34 -> 0 | C21: ='Course Information'!D34 -> 0 | E21: =IFERROR(ROUNDUP((D21/$E$9)*100,0),"") -> 0 | F21: =Evaluation!AF18 -> 0
A22: 12 | B22: ='Course Information'!B35 -> 0 | C22: ='Course Information'!D35 -> 0 | E22: =IFERROR(ROUNDUP((D22/$E$9)*100,0),"") -> 0 | F22: =Evaluation!AF19 -> 0
... A76: 66 | B76: ='Course Information'!B89 -> 0 | C76: ='Course Information'!D89 -> 0 | E76: =IFERROR(ROUNDUP((D76/$E$9)*100,0),"") -> 0 | F76: =Evaluation!AF73 -> 0
A77: Total Number of Students | E77: =COUNTA('[1]Student List'!B7:B96) -> 90
A78: Number of Absentees | E78: =COUNTIF(F11:F76,"AB") -> 0
A79: Number of Students Scoring Between 0 & 20 | E79: =COUNTIF(F11:F76,"<=20") -> 66
A80: Number of Students Scoring Between 21 & 40 | E80: =COUNTIF(F11:F76,"<=40")-E79 -> 0
A81: Number of Students Scoring Between 41 & 50 | E81: =COUNTIF(F11:F76,">=41") -> 0
A82: Number of Students with Less than 85% Attendance | E82: =COUNTIF(E11:E76,"<85") -> 66
A86: (Signature of Course Instructor) (Signature of the HOD)

Sheet Overall Summary
A1: PES INSTITUTE OF TECHNOLOGY & MANAGEMENT
A2: NH-206, SAGAR ROAD, SHIVAMOGGA - 577204
A3: PESITM - IQAC - Form 22 / R0 – CIE & SEE Marks
A4: DEPARTMENT OF xxxxxx ENGINEERING
A5: Course Name: | C5: ='Course Information'!$F$6 -> DATA STRUCTURE AND APPLICATIONS
A6: Academic Year: | C6: ='Course Information'!$F$5 -> 2026-27 | G6: Semester : | H6: ='Course Information'!N5 -> III | J6: Section: | K6: ='Course Information'!P5 -> A
A7: Course Code: | C7: ='Course Information'!$F$7 -> 1BCS305 | G7: NBA Code: | H7: ='Course Information'!N7 -> 0
A8: Scheme of Study: | E8: CIE : SEE | G8: ='Course Information'!N9 -> 50 | I8: Date:
A9: Sl. No. | B9: Name of the Student | C9: USN | D9: IA 1 | E9: IA 2 | F9: IA3 | G9: CCE 1 | H9: CCE 2 | I9: CCE 3 | J9: CIE Marks | K9: SEE Marks
A10: 1 | B10: ='Course Information'!D24 -> 0 | C10: ='Course Information'!B24 -> 0 | D10: =Evaluation!N8 -> 0 | E10: =Evaluation!AF8 -> 0 | G10: =Evaluation!T8 -> 0 | H10: =Evaluation!AL8 -> 0 | K10: =Evaluation!BF8 -> 0
A11: 2 | B11: ='Course Information'!D25 -> 0 | C11: ='Course Information'!B25 -> 0 | D11: =Evaluation!N9 -> 0 | E11: =Evaluation!AF9 -> 0 | G11: =Evaluation!T9 -> 0 | H11: =Evaluation!AL9 -> 0 | K11: =Evaluation!BF9 -> 0
A12: 3 | B12: ='Course Information'!D26 -> 0 | C12: ='Course Information'!B26 -> 0 | D12: =Evaluation!N10 -> 0 | E12: =Evaluation!AF10 -> 0 | G12: =Evaluation!T10 -> 0 | H12: =Evaluation!AL10 -> 0 | K12: =Evaluation!BF10 -> 0
A13: 4 | B13: ='Course Information'!D27 -> 0 | C13: ='Course Information'!B27 -> 0 | D13: =Evaluation!N11 -> 0 | E13: =Evaluation!AF11 -> 0 | G13: =Evaluation!T11 -> 0 | H13: =Evaluation!AL11 -> 0 | K13: =Evaluation!BF11 -> 0
A14: 5 | B14: ='Course Information'!D28 -> 0 | C14: ='Course Information'!B28 -> 0 | D14: =Evaluation!N12 -> 0 | E14: =Evaluation!AF12 -> 0 | G14: =Evaluation!T12 -> 0 | H14: =Evaluation!AL12 -> 0 | K14: =Evaluation!BF12 -> 0
A15: 6 | B15: ='Course Information'!D29 -> 0 | C15: ='Course Information'!B29 -> 0 | D15: =Evaluation!N13 -> 0 | E15: =Evaluation!AF13 -> 0 | G15: =Evaluation!T13 -> 0 | H15: =Evaluation!AL13 -> 0 | K15: =Evaluation!BF13 -> 0
A16: 7 | B16: ='Course Information'!D30 -> 0 | C16: ='Course Information'!B30 -> 0 | D16: =Evaluation!N14 -> 0 | E16: =Evaluation!AF14 -> 0 | G16: =Evaluation!T14 -> 0 | H16: =Evaluation!AL14 -> 0 | K16: =Evaluation!BF14 -> 0
A17: 8 | B17: ='Course Information'!D31 -> 0 | C17: ='Course Information'!B31 -> 0 | D17: =Evaluation!N15 -> 0 | E17: =Evaluation!AF15 -> 0 | G17: =Evaluation!T15 -> 0 | H17: =Evaluation!AL15 -> 0 | K17: =Evaluation!BF15 -> 0
A18: 9 | B18: ='Course Information'!D32 -> 0 | C18: ='Course Information'!B32 -> 0 | D18: =Evaluation!N16 -> 0 | E18: =Evaluation!AF16 -> 0 | G18: =Evaluation!T16 -> 0 | H18: =Evaluation!AL16 -> 0 | K18: =Evaluation!BF16 -> 0
A19: 10 | B19: ='Course Information'!D33 -> 0 | C19: ='Course Information'!B33 -> 0 | D19: =Evaluation!N17 -> 0 | E19: =Evaluation!AF17 -> 0 | G19: =Evaluation!T17 -> 0 | H19: =Evaluation!AL17 -> 0 | K19: =Evaluation!BF17 -> 0
A20: 11 | B20: ='Course Information'!D34 -> 0 | C20: ='Course Information'!B34 -> 0 | D20: =Evaluation!N18 -> 0 | E20: =Evaluation!AF18 -> 0 | G20: =Evaluation!T18 -> 0 | H20: =Evaluation!AL18 -> 0 | K20: =Evaluation!BF18 -> 0
A21: 12 | B21: ='Course Information'!D35 -> 0 | C21: ='Course Information'!B35 -> 0 | D21: =Evaluation!N19 -> 0 | E21: =Evaluation!AF19 -> 0 | G21: =Evaluation!T19 -> 0 | H21: =Evaluation!AL19 -> 0 | K21: =Evaluation!BF19 -> 0
... A76: 67 | B76: ='Course Information'!D90 -> 0 | C76: ='Course Information'!B90 -> 0 | D76: =Evaluation!N74 -> 0 | E76: =Evaluation!AF74 -> 0 | G76: =Evaluation!T74 -> 0 | H76: =Evaluation!AL74 -> 0 | K76: =Evaluation!BF74 -> 0
A78: Average Marks
A79: Percentage of Marks Scored
A83: (Signature of Course Instructor) | F83: (Signature of HOD)
A84: Name of Course Instructor
C1047: =IFERROR(__xludf.DUMMYFUNCTION("IMPORTRANGE(""https://docs.google.com/spreadsheets/d/100SUI2T68D_gTbJNbbofFQQ3SxlpiPS6ANKvacMBnR0/edit?gid=1438031345#gid=1438031345"",""Course Information!B24"")"),"#REF!") -> #REF!

Sheet COs & Mapping
A1: PES INSTITUTE OF TECHNOLOGY & MANAGEMENT
A2: NH-206, SAGAR ROAD, SHIVAMOGGA - 577204
A3: PESITM - IQAC - Record No. 4A / R1 - CO's and Mapping with PO's & PSO's
A4: DEPARTMENT OF INFORMATION SCIENCE AND ENGINEERING
A5: Academic Year: | C5: ='Course Information'!$F$5 -> 2026-27 | I5: Semester: | K5: ='Course Information'!N5 -> III
A6: Course Name: | C6: Project Management (with Git) | I6: Course Code: | K6: 1BCSL307A
A7: Course Instructor: | C7: ='Course Information'!$F$8 -> Thara K L | I7: Date:
A8: Course Outcomes
A9: CO1 | B9: Demonstrate the use of basic Git repository commands for version control operations.
A10: CO2 | B10: Implement branch management strategies for collaborative software development
A11: CO3 | B11: Apply collaboration techniques using remote repositories and distributed version control systems.
A12: CO4 | B12: Configure Git tags, releases, and advanced Git operations for effective project management.
A13: CO5 | B13: Modify Git history to maintain repository integrity and support project requirements.
A14: CO -PO Articulation Matrix
B15: PO1 | C15: PO2 | D15: PO3 | E15: PO4 | F15: PO5 | G15: PO6 | H15: PO7 | I15: PO8 | J15: PO9 | K15: PO10 | L15: PO11
A16: CO1 | B16: ='Course Information'!$C$13 -> 0 | C16: 3 | D16: ='Course Information'!$E$13 -> 0 | E16: ='Course Information'!$F$13 -> 0 | F16: 3 | G16: ='Course Information'!$H$13 -> 0 | H16: ='Course Information'!$I$13 -> 0 | I16: ='Course Information'!$J$13 -> 0 | J16: ='Course Information'!$K$13 -> 0 | K16: ='Course Information'!$L$13 -> 0 | L16: ='Course Information'!$M$13 -> 0
A17: CO2 | B17: ='Course Information'!$C$14 -> 0 | C17: 3 | D17: ='Course Information'!$E$14 -> 0 | E17: ='Course Information'!$F$14 -> 0 | F17: 3 | G17: ='Course Information'!$H$14 -> 0 | H17: ='Course Information'!$I$14 -> 0 | I17: ='Course Information'!$J$14 -> 0 | J17: 3 | K17: ='Course Information'!$L$14 -> 0 | L17: ='Course Information'!$M$14 -> 0
A18: CO3 | B18: ='Course Information'!$C$115 -> 0 | C18: ='Course Information'!$D$15 -> 0 | D18: ='Course Information'!$E$15 -> 0 | E18: ='Course Information'!$F$15 -> 0 | F18: 3 | G18: ='Course Information'!$H$15 -> 0 | H18: ='Course Information'!$I$15 -> 0 | I18: ='Course Information'!$J$15 -> 0 | J18: 3 | K18: ='Course Information'!$L$15 -> 0 | L18: ='Course Information'!$M$15 -> 0
A19: CO4 | B19: ='Course Information'!$C$116 -> 0 | C19: 3 | D19: ='Course Information'!$E$16 -> 0 | E19: ='Course Information'!$F$16 -> 0 | F19: 3 | G19: ='Course Information'!$H$16 -> 0 | H19: ='Course Information'!$I$16 -> 0 | I19: ='Course Information'!$J$16 -> 0 | J19: ='Course Information'!$K$16 -> 0 | K19: ='Course Information'!$L$16 -> 0 | L19: ='Course Information'!$M$16 -> 0
A20: CO5 | B20: ='Course Information'!$C$17 -> 0 | C20: 3 | D20: ='Course Information'!$E$17 -> 0 | E20: ='Course Information'!$F$17 -> 0 | F20: 3 | G20: ='Course Information'!$H$17 -> 0 | H20: ='Course Information'!$I$17 -> 0 | I20: ='Course Information'!$J$17 -> 0 | J20: ='Course Information'!$K$17 -> 0 | K20: ='Course Information'!$L$17 -> 0 | L20: ='Course Information'!$M$17 -> 0
A21: Achievable | B21: ='Course Information'!$C$19 -> NA | C21: 3 | D21: ='Course Information'!$E$19 -> NA | E21: ='Course Information'!$F$19 -> NA | F21: 3 | G21: ='Course Information'!$H$19 -> NA | H21: ='Course Information'!$I$19 -> NA | I21: ='Course Information'!$J$19 -> NA | J21: 3 | K21: ='Course Information'!$L$19 -> NA | L21: ='Course Information'!$M$19 -> NA
A22: CO -PSO Articulation Matrix
B23: PSO1 | F23: PSO2 | J23: PSO3
A24: CO1 | B24: 3 | F24: ='Course Information'!$P$13 -> 0 | J24: 3
A25: CO2 | B25: 3 | F25: ='Course Information'!$P$14 -> 0 | J25: 3
A26: CO3 | B26: 3 | F26: ='Course Information'!$P$15 -> 0 | J26: 3
A27: CO4 | B27: 3 | F27: ='Course Information'!$P$16 -> 0 | J27: 3
A28: CO5 | B28: 3 | F28: ='Course Information'!$P$17 -> 0 | J28: 3
A29: Achievable | B29: 3 | F29: ='Course Information'!$P$19 -> NA | J29: 3
A32: Signature of Course Instructor | H32: (Signature of HOD)

Sheet Justification
A1: PES INSTITUTE OF TECHNOLOGY & MANAGEMENT
A2: NH-206, SAGAR ROAD, SHIVAMOGGA - 577204
A3: PESITM - IQAC - Record No. 4B / R0 - Justifiation for Mapping of CO's with PO's & PSO's
A4: DEPARTMENT OF INFORMATION SCIENCE AND ENGINEERING
A5: Academic Year: | C5: ='Course Information'!$F$5 -> 2026-27 | I5: Semester: | K5: ='Course Information'!N5 -> III
A6: Course Name: | C6: Project Management (with Git) | I6: Course Code: | K6: 1BCSL307A
A7: Course Instructor: | C7: ='Course Information'!F8 -> Thara K L | I7: Date:
A8: CO's | B8: PO / PSO | D8: Mapping | F8: Justification
A9: CO1 | B9: PO2 | D9: 3 | F9: Analyses basic version-control requirements and selects suitable Git commands.
B10: PO5 | D10: 3 | F10: Use Git commands to create repositories, stage files, and commit changes.
B11: PSO1 | D11: 3 | F11: Apply the basic Git commands to implement version-control operations in software projects.
B12: PSO3 | D12: 3 | F12: Applies version-control practices to maintain software project files systematically.
A13: CO2 | B13: PO2 | D13: 3 | F13: Analyse branch changes and select suitable branching and merging operations.
B14: PO5 | D14: 3 | F14: Implement Git branching, switching, merging, and stashing operations.
B15: PO9 | D15: 3 | F15: Apply branching and merging practices for collaborative software development.
B16: PSO1 | D16: 3 | F16: Implements branching and merging operations to manage software development tasks.
B17: PSO3 | D17: 3 | F17: Applies branching and merging practices for organized software development.
A18: CO3 | B18: PO5 | D18: 3 | F18: Students will be able to apply Git commands to clone, fetch, rebase, and merge remote repositories.
B19: PO9 | D19: 3 | F19: Apply remote repository practices for collaborative software development.
B20: PSO1 | D20: 3 | F20: Implements remote repository operations to support distributed software development.
B21: PSO3 | D21: 3 | F21: Applies collaborative version-control practices for software development.
A22: CO4 | B22: PO2 | D22: 3 | F22: Analyse version-management requirements and select suitable Git operations.
B23: PO5 | D23: 3 | F23: Apply tags, releases, and cherry-pick operations using Git.
B24: PSO1 | D24: 3 | F24: Applies advanced Git operations to manage different versions of software projects.
B25: PSO3 | D25: 3 | F25: Applies tagging, release, and change-management practices to support quality software development.
A26: CO5 | B26: PO2 | D26: 3 | F26: Analyse Git history and select suitable operations to manage changes.
B27: PO5 | D27: 3 | F27: To modify and manage Git history using appropriate Git commands.
B28: PSO1 | D28: 3 | F28: Analyses and modifies Git history to manage software changes effectively.
B29: PSO3 | D29: 3 | F29: Applies version-history management practices to maintain software project integrity.
A33: Signature of Course Instructor | H33: Signature of HOD

Sheet Individual TT
A1: PES INSTITUTE OF TECHNOLOGY & MANAGEMENT
A2: NH-206, SAGAR ROAD, SHIVAMOGGA - 577204
A3: PESITM - IQAC - Record No. 3B / R0 - Individual Timetable
A4: DEPARTMENT OF XXXXX ENGINEERING
A5: Name of the Faculty: | C5: ='Course Information'!F8 -> Thara K L | F5: Designation: | H5: ASSISTANT PROFESSOR
A6: Academic Year: | C6: ='Course Information'!$F$5 -> 2026-27 | F6: Date: | H6: Effective From: 31-8-2026
A7: Day / Time | B7: 08:00 to 09:00 | C7: 09:00 to 10:00 | D7: 10:00 to 10:30 | E7: 10:30 to 11:30 | F7: 11:30 to 12:30 | G7: 12:30 to 01:30 | H7: 01:30 to 02:30 | I7: 02:30 to 03:30 | J7: 03:30 to 04:30
A8: Monday | D8: B R E A K | G8: L U N C H
A9: Tuesday
A10: Wednesday | E10: GIT LAB
A11: Thursday
A12: Friday | E12: GIT LAB
A13: Saturday
A15: Semester | B15: Course Name | F15: Course Code | H15: Hours | I15: Units | J15: Total Workload
A22: Additional Responsibilities
A23: 1
A24: 2
A25: 3
A26: 4
A27: 5
A28: 6
A32: Signature of Coordinator | G32: (Signature of HOD)
A33: (Name of Coordinator)

Sheet Lesson_Theory
A1: PES INSTITUTE OF TECHNOLOGY & MANAGEMENT
A2: NH-206, SAGAR ROAD, SHIVAMOGGA - 577204
A3: PESITM - IQAC - Record No. 05 A / R3 - Lesson Schedule (Theory Course)
A4: DEPARTMENT OF INFORMATION SCIENCE ENGINEERING
A5: Acadmic Year: | C5: 2026-27 | D5: Semester: | E5: 3 | F5: Date: | G5: 46265
A6: Course Name: | C6: Data Structures and Applications | F6: Course Code: | G6: 1BCS305
A7: Course Instructor: | C7: Mrs. Thara K L | E7: Total Hours of Pedagogy:
A8: Teaching Hours per Week (L:T:P:S): Commencement of Semester: Last Working Day:
A9: Lecture Number | B9: Module | C9: Topics to be Covered | D9: Planned Date | E9: Date of Delivery | F9: Rescheduled Date (In case of deviation) | G9: Mode of Content Delivery
A10: 1 | B10: MODULE 1
A11: 2
A12: 3
A13: 4
A14: 5
A15: 6
A16: 7
A17: 8
